<sdf version="1.9">
<model name="rover2025" canonical_link="robot_root">
  <joint name="gps_locator" type="fixed">
    <pose relative_to="robot_root">0.09323 0.00000 0.65743 0.00000 0.00000 0.00000</pose>
    <parent>robot_root</parent>
    <child>gps</child>
    <axis>
      <xyz>0.00000 0.00000 1.00000</xyz>
    </axis>
    <axis2/>
  </joint>
  <joint name="robot_base_joint" type="fixed">
    <pose relative_to="robot_root">0.00000 0.00000 -0.00050 -0.00000 -0.00000 0.00000</pose>
    <parent>robot_root</parent>
    <child>robot_base</child>
    <axis/>
    <axis2/>
  </joint>
  <joint name="wheel_R_front" type="continuous">
    <pose relative_to="robot_wheel_l_front_actuator_link.008">-0.00000 -0.00000 -0.15555 -0.00000 -0.00000 0.00000</pose>
    <parent>robot_wheel_l_front_actuator_link.008</parent>
    <child>robot_wheel_l_front_actuator_link.009</child>
    <axis>
      <limit>
        <effort>0.00000</effort>
        <velocity>0.00000</velocity>
      </limit>
      <xyz>0.00000 -1.00000 0.00000</xyz>
    </axis>
    <axis2/>
  </joint>
  <joint name="imu_joint" type="fixed">
    <pose relative_to="robot_base">-0.00000 -0.00000 0.43039 -0.00000 0.00000 -0.00000</pose>
    <parent>robot_base</parent>
    <child>imu</child>
    <axis/>
    <axis2/>
  </joint>
  <joint name="rotate_L_back" type="revolute">
    <pose relative_to="robot_base">0.43705 -0.37063 0.32476 -0.00000 -0.00000 0.00000</pose>
    <parent>robot_base</parent>
    <child>robot_wheel_l_front_actuator_link.005</child>
    <axis>
      <limit>
        <lower>-2.96706</lower>
        <upper>2.96706</upper>
        <effort>0.00000</effort>
        <velocity>0.00000</velocity>
      </limit>
      <xyz>0.00000 0.00000 1.00000</xyz>
    </axis>
    <axis2/>
  </joint>
  <joint name="wheel_L_back" type="continuous">
    <pose relative_to="robot_wheel_l_front_actuator_link.005">-0.00000 0.00000 -0.15555 0.00000 -0.00000 -0.00000</pose>
    <parent>robot_wheel_l_front_actuator_link.005</parent>
    <child>robot_wheel_l_front_actuator_link.006</child>
    <axis>
      <limit>
        <effort>0.00000</effort>
        <velocity>0.00000</velocity>
      </limit>
      <xyz>0.00000 -1.00000 0.00000</xyz>
    </axis>
    <axis2/>
  </joint>
  <joint name="rotate_L_front" type="revolute">
    <pose relative_to="robot_base">-0.57753 -0.37063 0.32476 -0.00000 -0.00000 0.00000</pose>
    <parent>robot_base</parent>
    <child>robot_wheel_l_front_actuator_link.003</child>
    <axis>
      <limit>
        <lower>-2.96706</lower>
        <upper>2.96706</upper>
        <effort>0.00000</effort>
        <velocity>0.00000</velocity>
      </limit>
      <xyz>0.00000 0.00000 1.00000</xyz>
    </axis>
    <axis2/>
  </joint>
  <joint name="wheel_L_front" type="continuous">
    <pose relative_to="robot_wheel_l_front_actuator_link.003">-0.00000 0.00000 -0.15555 0.00000 -0.00000 -0.00000</pose>
    <parent>robot_wheel_l_front_actuator_link.003</parent>
    <child>robot_wheel_l_front_actuator_link.004</child>
    <axis>
      <limit>
        <effort>0.00000</effort>
        <velocity>0.00000</velocity>
      </limit>
      <xyz>0.00000 -1.00000 0.00000</xyz>
    </axis>
    <axis2/>
  </joint>
  <joint name="rotate_R_back" type="revolute">
    <pose relative_to="robot_base">0.43705 0.32063 0.32476 0.00000 -0.00000 -3.14159</pose>
    <parent>robot_base</parent>
    <child>robot_wheel_l_front_actuator_link.011</child>
    <axis>
      <limit>
        <lower>-2.96706</lower>
        <upper>2.96706</upper>
        <effort>0.00000</effort>
        <velocity>0.00000</velocity>
      </limit>
      <xyz>0.00000 0.00000 1.00000</xyz>
    </axis>
    <axis2/>
  </joint>
  <joint name="wheel_R_back" type="continuous">
    <pose relative_to="robot_wheel_l_front_actuator_link.011">0.00000 0.00000 -0.15555 -0.00000 -0.00000 0.00000</pose>
    <parent>robot_wheel_l_front_actuator_link.011</parent>
    <child>robot_wheel_l_front_actuator_link.012</child>
    <axis>
      <limit>
        <effort>0.00000</effort>
        <velocity>0.00000</velocity>
      </limit>
      <xyz>0.00000 -1.00000 0.00000</xyz>
    </axis>
    <axis2/>
  </joint>
  <joint name="rotate_R_front" type="revolute">
    <pose relative_to="robot_base">-0.57753 0.32063 0.32476 0.00000 -0.00000 -3.14159</pose>
    <parent>robot_base</parent>
    <child>robot_wheel_l_front_actuator_link.008</child>
    <axis>
      <limit>
        <lower>-2.96706</lower>
        <upper>2.96706</upper>
        <effort>0.00000</effort>
        <velocity>0.00000</velocity>
      </limit>
      <xyz>0.00000 0.00000 1.00000</xyz>
    </axis>
    <axis2/>
  </joint>
  <link name="robot_root">
    <collision name="body_collision">
      <pose relative_to="robot_root">0.00000 0.00000 0.00000 0.00000 0.00000 0.00000</pose>
      <geometry>
        <box>
          <size>5.69672 4.01711 2.92977</size>
        </box>
      </geometry>
      <surface>
        <contact/>
      </surface>
    </collision>
  </link>
  <link name="gps">
    <sensor name="gps.001" type="GPS">
      <always_on>1</always_on>
      <visualize>1</visualize>
      <enable_metrics>1</enable_metrics>
    </sensor>
  </link>
  <link name="robot_wheel_l_front_actuator_link.008">
    <inertial>
      <inertia>
        <ixx>0.00100</ixx>
        <ixy>0.00000</ixy>
        <ixz>0.00000</ixz>
        <iyy>0.00100</iyy>
        <iyz>-0.00000</iyz>
        <izz>0.00100</izz>
      </inertia>
      <pose relative_to="robot_wheel_l_front_actuator_link.008">0.00000 0.00000 -0.00000 0.00000 0.00000 0.00000</pose>
      <mass>1.00000</mass>
    </inertial>
    <visual name="bone-r-1">
      <pose relative_to="robot_wheel_l_front_actuator_link.008">-0.00377 0.00334 0.07903 0.00000 0.00000 1.57080</pose>
      <geometry>
        <mesh>
          <uri>../meshes/stl/Science.422.stl</uri>
          <scale>1 1 1</scale>
        </mesh>
      </geometry>
    </visual>
  </link>
  <link name="robot_wheel_l_front_actuator_link.009">
    <collision name="wheel-r-1_collision">
      <pose relative_to="robot_wheel_l_front_actuator_link.009">-0.57753 0.32063 -0.16871 0.00000 -0.00000 3.14159</pose>
      <geometry>
        <cylinder>
          <radius>0.78907</radius>
          <length>0.71014</length>
        </cylinder>
      </geometry>
      <surface>
        <contact/>
      </surface>
    </collision>
    <visual name="wheel-r-1">
      <pose relative_to="robot_wheel_l_front_actuator_link.009">-0.00334 0.00643 0.01418 0.00000 0.00000 1.57080</pose>
      <geometry>
        <cylinder>
          <radius>0.06742</radius>
          <length>0.32599</length>
        </cylinder>
      </geometry>
    </visual>
  </link>
  <link name="robot_base">
    <visual name="body">
      <pose relative_to="robot_base">-0.00000 -0.00000 0.00050 -0.00000 0.00000 -0.00000</pose>
      <geometry>
        <box>
          <size>1.09671 0.77336 0.78564</size>
        </box>
      </geometry>
    </visual>
  </link>
  <link name="imu">
    <sensor name="imu-sensor" type="imu">
      <always_on>1</always_on>
      <visualize>0</visualize>
      <enable_metrics>0</enable_metrics>
    </sensor>
  </link>
  <link name="robot_wheel_l_front_actuator_link.005">
    <inertial>
      <inertia>
        <ixx>0.00100</ixx>
        <ixy>-0.00000</ixy>
        <ixz>-0.00000</ixz>
        <iyy>0.00100</iyy>
        <iyz>0.00000</iyz>
        <izz>0.00100</izz>
      </inertia>
      <pose relative_to="robot_wheel_l_front_actuator_link.005">0.00000 0.00000 -0.00000 0.00000 0.00000 0.00000</pose>
      <mass>1.00000</mass>
    </inertial>
    <visual name="bone-l-2">
      <pose relative_to="robot_wheel_l_front_actuator_link.005">-0.00056 0.00243 0.06913 -0.00000 -0.00000 -1.57080</pose>
      <geometry>
        <mesh>
          <uri>../meshes/stl/Science.479.stl</uri>
          <scale>1 1 1</scale>
        </mesh>
      </geometry>
    </visual>
  </link>
  <link name="robot_wheel_l_front_actuator_link.006">
    <collision name="wheel-l-2_collision">
      <pose relative_to="robot_wheel_l_front_actuator_link.006">-0.43705 0.37063 -0.16871 0.00000 0.00000 0.00000</pose>
      <geometry>
        <cylinder>
          <radius>0.78567</radius>
          <length>0.93707</length>
        </cylinder>
      </geometry>
      <surface>
        <contact/>
      </surface>
    </collision>
    <visual name="wheel-l-2">
      <pose relative_to="robot_wheel_l_front_actuator_link.006">-0.00094 0.00902 0.00436 -0.00000 -0.00000 -1.57080</pose>
      <geometry>
        <cylinder>
          <radius>0.08897</radius>
          <length>0.32599</length>
        </cylinder>
      </geometry>
    </visual>
  </link>
  <link name="robot_wheel_l_front_actuator_link.003">
    <inertial>
      <inertia>
        <ixx>0.00100</ixx>
        <ixy>-0.00000</ixy>
        <ixz>-0.00000</ixz>
        <iyy>0.00100</iyy>
        <iyz>0.00000</iyz>
        <izz>0.00100</izz>
      </inertia>
      <pose relative_to="robot_wheel_l_front_actuator_link.003">0.00000 0.00000 -0.00000 0.00000 0.00000 0.00000</pose>
      <mass>1.00000</mass>
    </inertial>
    <visual name="bone-l-1">
      <pose relative_to="robot_wheel_l_front_actuator_link.003">0.00364 0.00244 0.07904 0.00000 -0.00000 1.57080</pose>
      <geometry>
        <mesh>
          <uri>../meshes/stl/Science.483.stl</uri>
          <scale>1 1 1</scale>
        </mesh>
      </geometry>
    </visual>
  </link>
  <link name="robot_wheel_l_front_actuator_link.004">
    <collision name="wheel-l-1_collision">
      <pose relative_to="robot_wheel_l_front_actuator_link.004">0.57753 0.37063 -0.16871 0.00000 0.00000 0.00000</pose>
      <geometry>
        <cylinder>
          <radius>0.78693</radius>
          <length>0.85322</length>
        </cylinder>
      </geometry>
      <surface>
        <contact/>
      </surface>
    </collision>
    <visual name="wheel-l-1">
      <pose relative_to="robot_wheel_l_front_actuator_link.004">0.00517 -0.00424 0.02084 0.00000 0.00000 1.57080</pose>
      <geometry>
        <cylinder>
          <radius>0.07091</radius>
          <length>0.32602</length>
        </cylinder>
      </geometry>
    </visual>
  </link>
  <link name="robot_wheel_l_front_actuator_link.011">
    <inertial>
      <inertia>
        <ixx>0.00100</ixx>
        <ixy>0.00000</ixy>
        <ixz>0.00000</ixz>
        <iyy>0.00100</iyy>
        <iyz>0.00000</iyz>
        <izz>0.00100</izz>
      </inertia>
      <pose relative_to="robot_wheel_l_front_actuator_link.011">0.00000 0.00000 -0.00000 0.00000 0.00000 0.00000</pose>
      <mass>1.00000</mass>
    </inertial>
    <visual name="bone-r-2">
      <pose relative_to="robot_wheel_l_front_actuator_link.011">0.00033 0.00341 0.06913 -0.00000 -0.00000 -1.57080</pose>
      <geometry>
        <mesh>
          <uri>../meshes/stl/Science.488.stl</uri>
          <scale>1 1 1</scale>
        </mesh>
      </geometry>
    </visual>
  </link>
  <link name="robot_wheel_l_front_actuator_link.012">
    <collision name="wheel-r-2_collision">
      <pose relative_to="robot_wheel_l_front_actuator_link.012">0.43705 0.32063 -0.16871 0.00000 -0.00000 3.14159</pose>
      <geometry>
        <cylinder>
          <radius>0.77344</radius>
          <length>0.78904</length>
        </cylinder>
      </geometry>
      <surface>
        <contact/>
      </surface>
    </collision>
    <visual name="wheel-r-2">
      <pose relative_to="robot_wheel_l_front_actuator_link.012">0.00013 0.01000 0.00436 -0.00000 0.00000 -1.57080</pose>
      <geometry>
        <cylinder>
          <radius>0.07492</radius>
          <length>0.32598</length>
        </cylinder>
      </geometry>
    </visual>
  </link>
</model>
</sdf>