<robot name="rover2025" version="1.0">
  <joint name="camera1" type="fixed">
    <origin rpy="-0.00000 1.57080 0.00000" xyz="0.33301 -0.09643 0.81950"/>
    <parent link="robot_root"/>
    <child link="new_link.000"/>
  </joint>
  <joint name="gps_locator" type="fixed">
    <origin rpy="0.00000 0.00000 0.00000" xyz="0.09323 0.00000 0.65743"/>
    <parent link="robot_root"/>
    <child link="gps"/>
    <axis xyz="0.00000 0.00000 1.00000"/>
  </joint>
  <joint name="wheel_R_front" type="continuous">
    <limit effort="0.00000" velocity="0.00000"/>
    <origin rpy="-0.00000 -0.00000 0.00000" xyz="-0.00000 -0.00000 -0.15555"/>
    <parent link="robot_wheel_l_front_actuator_link.008"/>
    <child link="robot_wheel_l_front_actuator_link.009"/>
    <axis xyz="0.00000 -1.00000 0.00000"/>
  </joint>
  <joint name="robot_base_joint" type="fixed">
    <origin rpy="-0.00000 -0.00000 0.00000" xyz="0.00000 0.00000 -0.00050"/>
    <parent link="robot_root"/>
    <child link="robot_base"/>
  </joint>
  <joint name="rotate_L_back" type="revolute">
    <limit lower="-2.96706" upper="2.96706" effort="0.00000" velocity="0.00000"/>
    <origin rpy="-0.00000 -0.00000 0.00000" xyz="0.43705 -0.37063 0.32476"/>
    <parent link="robot_base"/>
    <child link="robot_wheel_l_front_actuator_link.005"/>
    <axis xyz="0.00000 0.00000 1.00000"/>
  </joint>
  <joint name="wheel_L_back" type="continuous">
    <limit effort="0.00000" velocity="0.00000"/>
    <origin rpy="0.00000 -0.00000 -0.00000" xyz="-0.00000 0.00000 -0.15555"/>
    <parent link="robot_wheel_l_front_actuator_link.005"/>
    <child link="robot_wheel_l_front_actuator_link.006"/>
    <axis xyz="0.00000 -1.00000 0.00000"/>
  </joint>
  <joint name="rotate_L_front" type="revolute">
    <limit lower="-2.96706" upper="2.96706" effort="0.00000" velocity="0.00000"/>
    <origin rpy="-0.00000 -0.00000 0.00000" xyz="-0.57753 -0.37063 0.32476"/>
    <parent link="robot_base"/>
    <child link="robot_wheel_l_front_actuator_link.003"/>
    <axis xyz="0.00000 0.00000 1.00000"/>
  </joint>
  <joint name="wheel_L_front" type="continuous">
    <limit effort="0.00000" velocity="0.00000"/>
    <origin rpy="0.00000 -0.00000 -0.00000" xyz="-0.00000 0.00000 -0.15555"/>
    <parent link="robot_wheel_l_front_actuator_link.003"/>
    <child link="robot_wheel_l_front_actuator_link.004"/>
    <axis xyz="0.00000 -1.00000 0.00000"/>
  </joint>
  <joint name="rotate_R_back" type="revolute">
    <limit lower="-2.96706" upper="2.96706" effort="0.00000" velocity="0.00000"/>
    <origin rpy="0.00000 -0.00000 -3.14159" xyz="0.43705 0.32063 0.32476"/>
    <parent link="robot_base"/>
    <child link="robot_wheel_l_front_actuator_link.011"/>
    <axis xyz="0.00000 0.00000 1.00000"/>
  </joint>
  <joint name="wheel_R_back" type="continuous">
    <limit effort="0.00000" velocity="0.00000"/>
    <origin rpy="-0.00000 -0.00000 0.00000" xyz="0.00000 0.00000 -0.15555"/>
    <parent link="robot_wheel_l_front_actuator_link.011"/>
    <child link="robot_wheel_l_front_actuator_link.012"/>
    <axis xyz="0.00000 -1.00000 0.00000"/>
  </joint>
  <joint name="rotate_R_front" type="revolute">
    <limit lower="-2.96706" upper="2.96706" effort="0.00000" velocity="0.00000"/>
    <origin rpy="0.00000 -0.00000 -3.14159" xyz="-0.57753 0.32063 0.32476"/>
    <parent link="robot_base"/>
    <child link="robot_wheel_l_front_actuator_link.008"/>
    <axis xyz="0.00000 0.00000 1.00000"/>
  </joint>
  <link name="robot_root">
    <collision name="body_collision">
      <origin rpy="0.00000 0.00000 0.00000" xyz="-0.01465 -0.00549 0.16037"/>
      <geometry>
        <box size="1.22213 0.86180 0.62853"/>
      </geometry>
    </collision>
  </link>
  <link name="new_link.000">
    <sensor name="rgbd" type="camera">
      <origin rpy="0.00000 0.00000 0.00000" xyz="-0.00000 0.00000 0.00000"/>
      <parent link="new_link.000"/>
      <camera>
        <image>
          <width>1080</width>
          <height>1920</height>
          <hfov>1.57080</hfov>
        </image>
      </camera>
    </sensor>
  </link>
  <link name="robot_wheel_l_front_actuator_link.008">
    <inertial>
      <inertia ixx="0.00100" ixy="0.00000" ixz="0.00000" iyy="0.00100" iyz="-0.00000" izz="0.00100"/>
      <origin rpy="0.00000 0.00000 0.00000" xyz="0.00000 0.00000 -0.00000"/>
      <mass value="1.00000"/>
    </inertial>
    <visual name="bone-r-1">
      <material name="None"/>
      <origin rpy="0.00000 0.00000 1.57080" xyz="-0.00377 0.00334 0.07903"/>
      <geometry>
        <mesh filename="../meshes/stl/Science.422.stl" scale="1 1 1"/>
      </geometry>
    </visual>
  </link>
  <link name="robot_wheel_l_front_actuator_link.009">
    <collision name="wheel-r-1_collision">
      <origin rpy="-1.48431 1.57080 -3.05510" xyz="-0.00072 0.00138 0.00304"/>
      <geometry>
        <cylinder radius="0.16928" length="0.15235"/>
      </geometry>
    </collision>
    <visual name="wheel-r-1">
      <material name="None"/>
      <origin rpy="0.00000 0.00000 1.57080" xyz="-0.00334 0.00643 0.01418"/>
      <geometry>
        <cylinder radius="0.06742" length="0.32599"/>
      </geometry>
    </visual>
  </link>
  <link name="gps">
    <sensor name="gps.001" type="GPS">
      <parent link="gps"/>
    </sensor>
  </link>
  <link name="robot_base">
    <visual name="body">
      <material name="None"/>
      <origin rpy="-0.00000 0.00000 -0.00000" xyz="-0.00000 -0.00000 0.00050"/>
      <geometry>
        <box size="1.09671 0.77336 0.78564"/>
      </geometry>
    </visual>
  </link>
  <link name="robot_wheel_l_front_actuator_link.005">
    <inertial>
      <inertia ixx="0.00100" ixy="-0.00000" ixz="-0.00000" iyy="0.00100" iyz="0.00000" izz="0.00100"/>
      <origin rpy="0.00000 0.00000 0.00000" xyz="0.00000 0.00000 -0.00000"/>
      <mass value="1.00000"/>
    </inertial>
    <visual name="bone-l-2">
      <material name="None"/>
      <origin rpy="-0.00000 -0.00000 -1.57080" xyz="-0.00056 0.00243 0.06913"/>
      <geometry>
        <mesh filename="../meshes/stl/Science.479.stl" scale="1 1 1"/>
      </geometry>
    </visual>
  </link>
  <link name="robot_wheel_l_front_actuator_link.006">
    <collision name="wheel-l-2_collision">
      <origin rpy="-1.65729 1.57080 -0.08649" xyz="-0.00000 0.00000 0.00000"/>
      <geometry>
        <cylinder radius="0.16855" length="0.20103"/>
      </geometry>
    </collision>
    <visual name="wheel-l-2">
      <material name="None"/>
      <origin rpy="-0.00000 -0.00000 -1.57080" xyz="-0.00094 0.00902 0.00436"/>
      <geometry>
        <cylinder radius="0.08897" length="0.32599"/>
      </geometry>
    </visual>
  </link>
  <link name="robot_wheel_l_front_actuator_link.003">
    <inertial>
      <inertia ixx="0.00100" ixy="-0.00000" ixz="-0.00000" iyy="0.00100" iyz="0.00000" izz="0.00100"/>
      <origin rpy="0.00000 0.00000 0.00000" xyz="0.00000 0.00000 -0.00000"/>
      <mass value="1.00000"/>
    </inertial>
    <visual name="bone-l-1">
      <material name="None"/>
      <origin rpy="0.00000 -0.00000 1.57080" xyz="0.00364 0.00244 0.07904"/>
      <geometry>
        <mesh filename="../meshes/stl/Science.483.stl" scale="1 1 1"/>
      </geometry>
    </visual>
  </link>
  <link name="robot_wheel_l_front_actuator_link.004">
    <collision name="wheel-l-1_collision">
      <origin rpy="-1.50651 1.57080 0.06429" xyz="0.00087 0.00096 0.00304"/>
      <geometry>
        <cylinder radius="0.16882" length="0.18304"/>
      </geometry>
    </collision>
    <visual name="wheel-l-1">
      <material name="None"/>
      <origin rpy="0.00000 0.00000 1.57080" xyz="0.00517 -0.00424 0.02084"/>
      <geometry>
        <cylinder radius="0.07091" length="0.32602"/>
      </geometry>
    </visual>
  </link>
  <link name="robot_wheel_l_front_actuator_link.011">
    <inertial>
      <inertia ixx="0.00100" ixy="0.00000" ixz="0.00000" iyy="0.00100" iyz="0.00000" izz="0.00100"/>
      <origin rpy="0.00000 0.00000 0.00000" xyz="0.00000 0.00000 -0.00000"/>
      <mass value="1.00000"/>
    </inertial>
    <visual name="bone-r-2">
      <material name="None"/>
      <origin rpy="-0.00000 -0.00000 -1.57080" xyz="0.00033 0.00341 0.06913"/>
      <geometry>
        <mesh filename="../meshes/stl/Science.488.stl" scale="1 1 1"/>
      </geometry>
    </visual>
  </link>
  <link name="robot_wheel_l_front_actuator_link.012">
    <collision name="wheel-r-2_collision">
      <origin rpy="-1.51965 1.57080 -3.09044" xyz="0.00003 0.00215 0.00094"/>
      <geometry>
        <cylinder radius="0.16593" length="0.16927"/>
      </geometry>
    </collision>
    <visual name="wheel-r-2">
      <material name="None"/>
      <origin rpy="-0.00000 0.00000 -1.57080" xyz="0.00013 0.01000 0.00436"/>
      <geometry>
        <cylinder radius="0.07492" length="0.32598"/>
      </geometry>
    </visual>
  </link>
</robot>