<?xml version="1.0"?>
<robot name="rover2025" xmlns:xacro="http://wiki.ros.org/xacro">

  <!-- Properties -->
  <xacro:property name="wheel_radius" value="0.15"/>
  <xacro:property name="wheel_width" value="0.12"/>
  <xacro:property name="track" value="0.6"/>
  <xacro:property name="wheelbase" value="0.8"/>
  <xacro:property name="base_mass" value="50.0"/>
  <xacro:property name="wheel_mass" value="3.0"/>

  <!-- Material definitions -->
  <material name="gray">
    <color rgba="0.5 0.5 0.5 1.0"/>
  </material>
  <material name="black">
    <color rgba="0.1 0.1 0.1 1.0"/>
  </material>

  <!-- Base link with proper inertial properties -->
  <link name="base_link">
    <visual>
      <origin xyz="0 0 0.1" rpy="0 0 0"/>
      <geometry>
        <box size="1.2 0.8 0.3"/>
      </geometry>
      <material name="gray"/>
    </visual>
    <collision>
      <origin xyz="0 0 0.1" rpy="0 0 0"/>
      <geometry>
        <box size="1.2 0.8 0.3"/>
      </geometry>
    </collision>
    <inertial>
      <mass value="${base_mass}"/>
      <inertia ixx="2.0" ixy="0.0" ixz="0.0" iyy="2.0" iyz="0.0" izz="2.0"/>
      <origin xyz="0 0 0.1" rpy="0 0 0"/>
    </inertial>
  </link>

  <!-- Wheel macro -->
  <xacro:macro name="wheel" params="name x y z yaw">
    <link name="${name}_wheel">
      <visual>
        <origin xyz="0 0 0" rpy="1.5708 0 ${yaw}"/>
        <geometry>
          <cylinder radius="${wheel_radius}" length="${wheel_width}"/>
        </geometry>
        <material name="black"/>
      </visual>
      <collision>
        <origin xyz="0 0 0" rpy="1.5708 0 ${yaw}"/>
        <geometry>
          <cylinder radius="${wheel_radius}" length="${wheel_width}"/>
        </geometry>
      </collision>
      <inertial>
        <mass value="${wheel_mass}"/>
        <inertia ixx="0.05" ixy="0.0" ixz="0.0" iyy="0.05" iyz="0.0" izz="0.025"/>
        <origin xyz="0 0 0" rpy="0 0 0"/>
      </inertial>
    </link>

    <joint name="${name}_wheel_joint" type="continuous">
      <parent link="base_link"/>
      <child link="${name}_wheel"/>
      <origin xyz="${x} ${y} ${z}" rpy="0 0 0"/>
      <axis xyz="0 1 0"/>
      <dynamics damping="0.1" friction="1.0"/>
      <limit effort="50.0" velocity="10.0"/>
    </joint>
  </xacro:macro>

  <!-- Instantiate wheels -->
  <xacro:wheel name="front_left" x="0.4" y="0.3" z="0" yaw="0"/>
  <xacro:wheel name="front_right" x="0.4" y="-0.3" z="0" yaw="0"/>
  <xacro:wheel name="rear_left" x="-0.4" y="0.3" z="0" yaw="0"/>
  <xacro:wheel name="rear_right" x="-0.4" y="-0.3" z="0" yaw="0"/>

  <!-- IMU -->
  <link name="imu_link">
    <inertial>
      <mass value="0.1"/>
      <inertia ixx="0.001" ixy="0.0" ixz="0.0" iyy="0.001" iyz="0.0" izz="0.001"/>
    </inertial>
  </link>

  <joint name="imu_joint" type="fixed">
    <parent link="base_link"/>
    <child link="imu_link"/>
    <origin xyz="0 0 0.25" rpy="0 0 0"/>
  </joint>

  <!-- GPS -->
  <link name="gps_link">
    <inertial>
      <mass value="0.05"/>
      <inertia ixx="0.0001" ixy="0.0" ixz="0.0" iyy="0.0001" iyz="0.0" izz="0.0001"/>
    </inertial>
  </link>

  <joint name="gps_joint" type="fixed">
    <parent link="base_link"/>
    <child link="gps_link"/>
    <origin xyz="0.1 0 0.3" rpy="0 0 0"/>
  </joint>

  <!-- Camera -->
  <link name="camera_link">
    <inertial>
      <mass value="0.2"/>
      <inertia ixx="0.001" ixy="0.0" ixz="0.0" iyy="0.001" iyz="0.0" izz="0.001"/>
    </inertial>
  </link>

  <joint name="camera_joint" type="fixed">
    <parent link="base_link"/>
    <child link="camera_link"/>
    <origin xyz="0.35 -0.1 0.85" rpy="-0.1 0.2 0.1"/>
  </joint>

  <!-- ROS2 Control -->
  <ros2_control name="rover2025_control" type="system">
    <hardware>
      <plugin>gazebo_ros2_control/GazeboSystem</plugin>
    </hardware>

    <joint name="front_left_wheel_joint">
      <command_interface name="velocity"/>
      <state_interface name="position"/>
      <state_interface name="velocity"/>
    </joint>
    <joint name="front_right_wheel_joint">
      <command_interface name="velocity"/>
      <state_interface name="position"/>
      <state_interface name="velocity"/>
    </joint>
    <joint name="rear_left_wheel_joint">
      <command_interface name="velocity"/>
      <state_interface name="position"/>
      <state_interface name="velocity"/>
    </joint>
    <joint name="rear_right_wheel_joint">
      <command_interface name="velocity"/>
      <state_interface name="position"/>
      <state_interface name="velocity"/>
    </joint>
  </ros2_control>

  <!-- Gazebo plugins -->
  <gazebo>
    <plugin name="imu_plugin" filename="libgazebo_ros_imu_sensor.so">
      <ros>
        <namespace>/rover</namespace>
        <remapping>~/imu:=imu/data</remapping>
      </ros>
      <imu>
        <angular_velocity>
          <x><noise type="gaussian"><mean>0.0</mean><stddev>2e-4</stddev></noise></x>
          <y><noise type="gaussian"><mean>0.0</mean><stddev>2e-4</stddev></noise></y>
          <z><noise type="gaussian"><mean>0.0</mean><stddev>2e-4</stddev></noise></z>
        </angular_velocity>
        <linear_acceleration>
          <x><noise type="gaussian"><mean>0.0</mean><stddev>1.7e-2</stddev></noise></x>
          <y><noise type="gaussian"><mean>0.0</mean><stddev>1.7e-2</stddev></noise></y>
          <z><noise type="gaussian"><mean>0.0</mean><stddev>1.7e-2</stddev></noise></z>
        </linear_acceleration>
      </imu>
    </plugin>
  </gazebo>

  <gazebo>
    <plugin name="gps_plugin" filename="libgazebo_ros_gps_sensor.so">
      <ros>
        <namespace>/rover</namespace>
        <remapping>~/gps:=gps/fix</remapping>
      </ros>
      <gps>
        <position_sensing>
          <horizontal>
            <noise type="gaussian"><mean>0.0</mean><stddev>3.0</stddev></noise>
          </horizontal>
          <vertical>
            <noise type="gaussian"><mean>0.0</mean><stddev>6.0</stddev></noise>
          </vertical>
        </position_sensing>
      </gps>
    </plugin>
  </gazebo>

  <gazebo>
    <plugin name="camera_plugin" filename="libgazebo_ros_camera.so">
      <ros>
        <namespace>/rover</namespace>
        <remapping>~/image_raw:=camera/image_raw</remapping>
        <remapping>~/camera_info:=camera/camera_info</remapping>
      </ros>
      <camera>
        <image>
          <width>1280</width>
          <height>720</height>
          <hfov>1.047</hfov>
        </image>
        <clip>
          <near>0.1</near>
          <far>100.0</far>
        </clip>
      </camera>
    </plugin>
  </gazebo>

</robot>
